Workbook
Name 머릿글: TestCase!$B$1:$J$1

Sheet TestCase
A1: No | B1: 대분류 | C1: 중분류 | D1: 소분류 | E1: 테스트 시나리오 | F1: 테스트 조건 | G1: 실행 순서 | H1: Pass Result | I1: P/F | J1: 실제 결과 | K1: Tag
B2: 게임실행 | C2: 실행 | D2: 게임실행 | E2: 클라이언트를 실행한다 | F2: 인게임 시작전 | G2: 1. "EclipseClassy.exe" 파일실행 | H2: 파일이 정상적으로 실행된다 | I2: Pass | J2: 파일이 정상적으로 실행된다 | K2: =IF(B2="",K1,B2) -> 게임실행 | L2: 이클립스클래시_BugTrackingList
C3: 윈도우 | D3: 최소화 | E3: 창을 최소화 한다 | F3: 인게임 시작전 | G3: 1. 최소화 버튼 클릭 | H3: 창이 최소화 된다 | I3: Pass | J3: 창이 최소화 된다 | K3: 게임실행 | L3: 이클립스클래시_테스트 결과 보고서.xlsx
D4: 닫기 | E4: 윈도우를 닫는다 | F4: 인게임 시작전 | G4: 1. 상단 X버튼 클릭 | H4: 창이 꺼지며 게임이 종료된다 | I4: Pass | J4: 창이 꺼지며 게임이 종료된다 | K4: 게임실행
B5: 메뉴기능 | C5: 게임메뉴 | D5: 닉네임 설정 | E5: 플레이어 닉네임을 설정한다 | F5: 메뉴 화면 | G5: 1. Input Your Nickname 클릭 2. 닉네임을 입력한다 | H5: 플레이어 닉네임이 설정된다 | I5: Pass | J5: 플레이어 닉네임이 설정된다 | K5: =IF(B5="",K4,B5) -> 메뉴기능
D6: 룸 이름 설정 | E6: 룸 이름을 설정한다 | F6: 메뉴 화면 | G6: 1. Room Name 클릭 2. 룸 이름을 입력한다 | H6: 룸 이름이 설정된다 | I6: Pass | J6: 룸 이름이 설정된다 | K6: 메뉴기능
D7: 룸 생성 | E7: 1 vs 1 랜덤 룸에 참여한다 | F7: 메뉴 화면 | G7: 1. 1vs1을 클릭한다 2. Random room을 클릭한다 3. 1vs1 랜덤 룸이 생성되고 룸에 입장한다 | H7: 1 vs 1 랜덤 룸에 입장된다 | I7: Pass | J7: 1 vs 1 랜덤 룸에 입장된다 | K7: =IF(B7="",K5,B7) -> 메뉴기능
E8: 2 vs 2 랜덤 룸에 참여한다 | F8: 메뉴 화면 | G8: 1. 2vs2를 클릭한다 2. Random room을 클릭한다 3. 2vs2 랜덤 룸이 생성되고 룸에 입장한다 | H8: 2 vs 2 랜덤 룸에 입장된다 | I8: Pass | J8: 2 vs 2 랜덤 룸에 입장된다 | K8: =IF(B7="",K5,B7) -> 메뉴기능
E9: 3 vs 3 랜덤 룸에 참여한다 | F9: 메뉴 화면 | G9: 1. 3vs3을 클릭한다 2. Random room을 클릭한다 3. 3vs3 랜덤 룸이 생성되고 룸에 입장한다 | H9: 3 vs 3 랜덤 룸에 입장된다 | I9: Pass | J9: 3 vs 3 랜덤 룸에 입장된다 | K9: =IF(B7="",K5,B7) -> 메뉴기능
E10: 1 vs 1 룸이 생성된다 | F10: 메뉴 화면 | G10: 1. 1vs1을 클릭한다 2. Create room을 클릭한다 3. 1vs1 룸이 생성되고 룸에 입장한다 | H10: 생성된 1 vs 1 룸에 입장된다 | I10: Pass | J10: 생성된 1 vs 1 룸에 입장된다 | K10: =IF(B7="",K5,B7) -> 메뉴기능
E11: 2 vs 2 룸이 생성된다 | F11: 메뉴 화면 | G11: 1. 2vs2를 클릭한다 2. Create room을 클릭한다 3. 2vs2 룸이 생성되고 룸에 입장한다 | H11: 생성된 2 vs 2 룸에 입장된다 | I11: Pass | J11: 생성된 2 vs 2 룸에 입장된다 | K11: =IF(B7="",K5,B7) -> 메뉴기능
E12: 3 vs 3 룸이 생성된다 | F12: 메뉴 화면 | G12: 1. 3vs3을 클릭한다 2. Create room을 클릭한다 3. 3vs3 룸이 생성되고 룸에 입장한다 | H12: 생성된 3 vs 3 룸에 입장된다 | I12: Pass | J12: 생성된 3 vs 3 룸에 입장된다 | K12: =IF(B7="",K5,B7) -> 메뉴기능
D13: 룸 | E13: 팀을 Red Team으로 변경한다 | F13: To Red 버튼 활성화 | G13: 1. To Red 버튼 클릭 2. 팀이 Red Team으로 변경된다 | H13: 팀이 Red Team으로 변경된다 | I13: Pass | J13: 팀이 Red Team으로 변경된다 | K13: =IF(B7="",K5,B7) -> 메뉴기능
E14: 팀을 Blue Team으로 변경한다 | F14: To Blue 버튼 활성화 | G14: 1. To Blue 버튼 클릭 2. 팀이 Blue Team으로 변경된다 | H14: 팀이 Blue Team으로 변경된다 | I14: Pass | J14: 팀이 Blue Team으로 변경된다 | K14: =IF(B7="",K5,B7) -> 메뉴기능
E15: 플레이어를 준비 상태로 변경한다 | F15: Ready 버튼 활성화 | G15: 1. Ready 버튼 클릭 2. 플레이어가 준비 상태로 변경된다 | H15: 플레이어가 준비 상태로 변경된다 | I15: Pass | J15: 플레이어가 준비 상태로 변경된다 | K15: =IF(B7="",K5,B7) -> 메뉴기능
E16: 대기중인 룸을 나간다 | F16: Exit room 버튼 활성화 | G16: 1. Exit room 클릭 2. 룸에서 나가진다 | H16: 룸에서 퇴장한다 | I16: Pass | J16: 룸에서 퇴장한다 | K16: =IF(B7="",K5,B7) -> 메뉴기능
E17: Start game 버튼을 클릭한 뒤 인게임으로 진입한다 | F17: 플레이어 전원 준비 상태 | G17: 1. 플레이어 전원이 준비 상태로 변경된다 2. Start game 버튼이 활성화된다 3. Start game 버튼 클릭 4. 인게임 화면으로 진입한다 | H17: 인게임 화면으로 진입한다 | I17: Pass | J17: 인게임 화면으로 진입한다 | K17: 메뉴기능
D18: 캐릭터 선택 | E18: 루미아를 캐릭터로 선택한다 | F18: 캐릭터 선택 화면 | G18: 1. 루미아를 선택한다 | H18: 루미아가 플레이어블 캐릭터로 선택된다. | I18: Pass | J18: 루미아가 플레이어블 캐릭터로 선택된다. | K18: =IF(B18="",K7,B18) -> 메뉴기능
E19: 캐릭터로 선택한다 | F19: 캐릭터 선택 화면 | H19: 캐릭터로 플레이어블 선택된다. | K19: =IF(B19="",K18,B19) -> 메뉴기능
E20: 캐릭터로 선택한다 | F20: 캐릭터 선택 화면 | H20: 캐릭터로 플레이어블 선택된다. | K20: =IF(B20="",K19,B20) -> 메뉴기능
E21: 셀레네를 캐릭터로 선택한다 | F21: 캐릭터 선택 화면 | H21: 셀레네가 캐릭터로 플레이어블 선택된다. | I21: N/A | J21: 셀레네가 캐릭터로 플레이어블 선택된다. | K21: =IF(B21="",K20,B21) -> 메뉴기능
E22: 캐릭터로 선택한다 | F22: 캐릭터 선택 화면 | H22: 캐릭터로 플레이어블 선택된다. | K22: =IF(B22="",K21,B22) -> 메뉴기능
E23: 캐릭터로 선택한다 | F23: 캐릭터 선택 화면 | H23: 캐릭터로 플레이어블 선택된다. | K23: =IF(B23="",K22,B23) -> 메뉴기능
B24: 캐릭터 | C24: 루미아 | D24: 기본 공격 | E24: 직선 상으로 화살을 발사한다 | G24: 1. 마우스 좌클릭 2. 기본 공격이 발사된다 | H24: 기본 공격이 사용된다 | I24: Pass | J24: 기본 공격이 사용된다 | K24: 인게임기능
D25: 폭풍화살 | E25: 연속으로 화살 3발을 0.35초당 1발씩 1초간 빠르게 발사한다 | F25: 스킬 - 폭풍화살 활성화 | G25: 1. 마우스 우클릭 2. 스킬이 사용된다 | H25: 스킬-폭풍화살이 사용되며 스킬 쿨타임이 돌아간다 | I25: Pass | J25: 스킬-폭풍화살이 사용되며 스킬 쿨타임이 돌아간다 | K25: 인게임기능
D26: 대쉬 | E26: WASD 버튼 방향에 맞추어 4의 거리 만큼 빠르게 이동한다 | F26: 스킬 - 대쉬 활성화 | G26: 1. Shift 키 입력 2. 캐릭터가 입력한 WASD키 방향에 맞추어 4의 거리를 빠르게 이동한다 | H26: 스킬-대쉬가 사용되며 스킬 쿨타임이 돌아간다 | I26: Pass | J26: 스킬-대쉬가 사용되며 스킬 쿨타임이 돌아간다 | K26: 인게임기능
D27: 궁극기 | E27: 명중한 적 플레이어에게 4의 범위에 3초간 초당 50의 데미지를 가한다 | F27: 스킬 - 궁극기 활성화 | G27: 1. R키 입력 2. 스킬 범위가 원형으로 표시된다 3. 스킬 위치 확정 시 스킬이 사용된다 | H27: 스킬-궁극기가 사용되며 스킬 쿨타임이 돌아간다 | I27: Pass | J27: 스킬-궁극기가 사용되며 스킬 쿨타임이 돌아간다 | K27: 인게임기능
C28: 캐릭터 2 | D28: 기본 공격 | K28: 인게임기능
D29: 스킬 1 | K29: 인게임기능
D30: 스킬 2 | K30: 인게임기능
D31: 궁극기 | K31: 인게임기능
C32: 캐릭터 3 | D32: 기본 공격 | K32: 인게임기능
D33: 스킬 1 | K33: 인게임기능
D34: 스킬 2 | K34: 인게임기능
D35: 궁극기 | K35: 인게임기능
C36: 셀레네 | D36: 기본 공격 | K36: 인게임기능
D37: 스킬 1 | K37: 인게임기능
D38: 스킬 2 | K38: 인게임기능
D39: 궁극기 | K39: 인게임기능
C40: 캐릭터 5 | D40: 기본 공격 | K40: 인게임기능
...

Sheet TC MAP
A1: 테스트케이스 현황
A2: 분류 | B2: 개수 | C2: 비율 | D2: Pass | E2: Fail | F2: N/A | G2: Block | H2: N/T | I2: Total | J2: Total(%)
A3: 게임실행 | B3: =COUNTIF(TestCase!K:K,A3) -> 3 | C3: =IFERROR(B3/$B$6,0) -> 0.052631579 | D3: =COUNTIFS(TestCase!$I:$I,"*"&D$2&"*",TestCase!$K:$K,$A3) -> 3 | E3: =COUNTIFS(TestCase!$I:$I,"*"&E$2&"*",TestCase!$K:$K,$A3) -> 0 | F3: =COUNTIFS(TestCase!$I:$I,"*"&F$2&"*",TestCase!$K:$K,$A3) -> 0 | G3: =COUNTIFS(TestCase!$I:$I,"*"&G$2&"*",TestCase!$K:$K,$A3) -> 0 | H3: =COUNTIFS(TestCase!$I:$I,"*"&H$2&"*",TestCase!$K:$K,$A3) -> 0 | I3: =COUNTIFS(TestCase!$I:$I,"*"&I$2&"*",TestCase!$K:$K,$A3) -> 0 | J3: =I3/B3 -> 0
A4: 메뉴기능 | B4: =COUNTIF(TestCase!K:K,A4) -> 19 | C4: =IFERROR(B4/$B$6,0) -> 0.33333333 | D4: =COUNTIFS(TestCase!$I:$I,"*"&D$2&"*",TestCase!$K:$K,$A4) -> 14 | E4: =COUNTIFS(TestCase!$I:$I,"*"&E$2&"*",TestCase!$K:$K,$A4) -> 0 | F4: =COUNTIFS(TestCase!$I:$I,"*"&F$2&"*",TestCase!$K:$K,$A4) -> 1 | G4: =COUNTIFS(TestCase!$I:$I,"*"&G$2&"*",TestCase!$K:$K,$A4) -> 0 | H4: =COUNTIFS(TestCase!$I:$I,"*"&H$2&"*",TestCase!$K:$K,$A4) -> 0 | I4: =SUM(D4:H4) -> 15 | J4: =I4/B4 -> 0.78947368
A5: 인게임기능 | B5: =COUNTIF(TestCase!K:K,A5) -> 35 | C5: =IFERROR(B5/$B$6,0) -> 0.61403509 | D5: =COUNTIFS(TestCase!$I:$I,"*"&D$2&"*",TestCase!$K:$K,$A5) -> 9 | E5: =COUNTIFS(TestCase!$I:$I,"*"&E$2&"*",TestCase!$K:$K,$A5) -> 0 | F5: =COUNTIFS(TestCase!$I:$I,"*"&F$2&"*",TestCase!$K:$K,$A5) -> 0 | G5: =COUNTIFS(TestCase!$I:$I,"*"&G$2&"*",TestCase!$K:$K,$A5) -> 0 | H5: =COUNTIFS(TestCase!$I:$I,"*"&H$2&"*",TestCase!$K:$K,$A5) -> 0 | I5: =SUM(D5:H5) -> 9 | J5: =I5/B5 -> 0.25714286
A6: Total | B6: =SUM(B3:B5) -> 57 | C6: =SUM(C3:C5) -> 1 | D6: =SUM(D3:D5) -> 26 | E6: =SUM(E3:E5) -> 0 | F6: =SUM(F3:F5) -> 1 | G6: =SUM(G3:G5) -> 0 | H6: =SUM(H3:H5) -> 0 | I6: =SUM(I3:I5) -> 24
A7: Total(%) | D7: =D6/$B6 -> 0.45614035 | E7: =E6/$B6 -> 0 | F7: =F6/$B6 -> 0.01754386 | G7: =G6/$B6 -> 0 | H7: =H6/$B6 -> 0 | I7: =I6/$B6 -> 0.42105263
